<mujoco model="hexapod2dofmoveforward">
  <compiler angle="degree" coordinate="local" inertiafromgeom="true" settotalmass="40"/>
  <option integrator="RK4" timestep="0.005"/>
  <default>
    <joint armature="1" damping="1" limited="true"/>
     <geom conaffinity="0" condim="3" density="5.0" friction="1 0.5 0.5" margin="0.01" rgba="0.8 0.6 0.4 1" material="geom"/>
  </default>
    <asset>
        <texture type="skybox" builtin="gradient" rgb1=".1 .12 .15" rgb2="0 0 0" width="100" height="100"/>
        <texture builtin="checker" height="100" name="texplane" rgb1=".1 .1 .1" rgb2=".15 .15 0.15" type="2d" width="100"/>
        <material name="MatPlane" reflectance="0.5" shininess="1" specular="1" texrepeat="50 50" texture="texplane"/>
        <texture builtin="flat" height="1278" mark="cross" markrgb="1 1 1" name="texgeom" random="0.01" rgb1="0.8 0.6 0.4" rgb2="0.8 0.6 0.4" type="cube" width="127"/>
        <material name="geom" texture="texgeom" texuniform="true"/>
    </asset>
  <worldbody>
    <light cutoff="100" diffuse="1 1 1" dir="-0 0 -1.3" directional="true" exponent="1" pos="0 0 1.3" specular=".1 .1 .1"/>
    <geom conaffinity="1" condim="3" material="MatPlane" name="floor" pos="0 0 0" rgba="0.8 0.9 0.8 1" size="40 40 40" type="plane"/>
      
    <body name="torso" pos="0 0 0.75">
      <geom name="torso_geom" pos="0 0 0" size="0.25" type="sphere"/>
      <joint armature="0" damping="0" limited="false" margin="0.01" name="root" pos="0 0 0" type="free"/>
      <!--
      <site name="torso_site" size='0.05 0.05 0.05'/>
      <site name="sensorsurf" pos="0 0.045 0" size=".03 .03 .03" type="ellipsoid" rgba="0.3 0.2 0.1 0.3"/>
    -->
      
    <!-- Back left leg -->
    <body name="back_left_leg" pos="0 0 0">
      <geom fromto="0 0 0 0.18 0.215 0" name="aux_1_geom" size="0.08" type="capsule"/>
      <body name="aux_11" pos="0.18 0.215 0">
        <joint axis="0 0 1" name="hip_1" pos="0 0 0" range="-30 30" type="hinge"/>
        <geom fromto="0 0 0 0.18 0.215 0" name="back_left_leg_geom" size="0.08" type="capsule"/>
        <body name="aux_12" pos="0.18 0.215 0">
          <joint axis="-1 1 0" name="ankle_1" pos="0 0 0" range="30 70" type="hinge"/>
          <geom fromto="0 0 0 0.324 0.387 0" name="back_left_ankle_geom" size="0.08" type="capsule"/>
        </body>
      </body>
    </body>
    <!-- Back right leg -->
    <body name="back_right_leg" pos="0 0 0">
      <geom fromto="0 0 0 -0.18 0.215 0" name="aux_2_geom" size="0.08" type="capsule"/>
      <body name="aux_21" pos="-0.18 0.215 0">
        <joint axis="0 0 1" name="hip_2" pos="0 0 0" range="-30 30" type="hinge"/>
        <geom fromto="0 0 0 -0.18 0.215 0" name="back_right_leg_geom" size="0.08" type="capsule"/>
        <body name="aux_22" pos="-0.18 0.215 0">
          <joint axis="1 1 0" name="ankle_2" pos="0 0 0" range="-70 -30" type="hinge"/>
          <geom fromto="0 0 0 -0.324 0.387 0" name="back_right_ankle_geom" size="0.08" type="capsule"/>
        </body>
      </body>
    </body>
     <!-- Middle left leg -->
    <body name="middle_left_leg" pos="0 0 0">
      <geom fromto="0 0 0 0.2 0 0" name="aux_4_geom" size="0.08" type="capsule"/>
      <body name="aux_41" pos="0.2 0 0">
        <joint axis="0 0 1" name="hip_4" pos="0 0 0" range="-30 30" type="hinge"/>
        <geom fromto="0 0 0 0.275 0 0" name="middle_left_leg_geom" size="0.08" type="capsule"/>
        <body name="aux_42" pos="0.275 0 0">
          <joint axis="0 1 0" name="ankle_4" pos="0 0 0" range="30 70" type="hinge"/>
          <geom fromto="0 0 0 0.55 0 0" name="middle_left_ankle_geom" size="0.08" type="capsule"/>
        </body>
      </body>
    </body>
    <!-- Middle right leg -->
    <body name="middle_right_leg" pos="0 0 0">
      <geom fromto="0 0 0 -0.2 0 0" name="aux_3_geom" size="0.08" type="capsule"/>
      <body name="aux_31" pos="-0.2 0 0">
        <joint axis="0 0 1" name="hip_3" pos="0 0 0" range="-30 30" type="hinge"/>
        <geom fromto="0 0 0 -0.275 0 0" name="middle_right_leg_geom" size="0.08" type="capsule"/>
        <body name="aux_32" pos="-0.275 0 0">
          <joint axis="0 1 0" name="ankle_3" pos="0 0 0" range="-70 -30" type="hinge"/>
          <geom fromto="0 0 0 -0.55 0 0" name="middle_right_ankle_geom" size="0.08" type="capsule"/>
        </body>
      </body>
    </body>

    <!-- Front left leg -->
    <body name="front_left_leg" pos="0 0 0">
      <geom fromto="0 0 0 0.18 -0.215 0" name="aux_6_geom" size="0.08" type="capsule"/>
      <body name="aux_61" pos="0.18 -0.215 0">
        <joint axis="0 0 1" name="hip_6" pos="0 0 0" range="-30 30" type="hinge"/>
        <geom fromto="0 0 0 0.18 -0.215 0" name="front_left_leg_geom" size="0.08" type="capsule"/>
        <body name="aux_62" pos="0.18 -0.215 0">
          <joint axis="1 1 0" name="ankle_6" pos="0 0 0" range="30 70" type="hinge"/>
          <geom fromto="0 0 0 0.324 -0.387 0" name="front_left_ankle_geom" size="0.08" type="capsule"/>
        </body>
      </body>
    </body>
    <!-- Front right leg -->
    <body name="front_right_leg" pos="0 0 0">
      <geom fromto="0 0 0 -0.18 -0.215 0" name="aux_5_geom" size="0.08" type="capsule"/>
      <body name="aux_51" pos="-0.18 -0.215 0">
        <joint axis="0 0 1" name="hip_5" pos="0 0 0" range="-30 30" type="hinge"/>
        <geom fromto="0 0 0 -0.18 -0.215 0" name="front_right_leg_geom" size="0.08" type="capsule"/>
        <body name="aux_52" pos="-0.18 -0.215 0">
          <joint axis="-1 1 0" name="ankle_5" pos="0 0 0" range="-70 -30" type="hinge"/>
          <geom fromto="0 0 0 -0.324 -0.387 0" name="front_right_ankle_geom" size="0.08" type="capsule"/>
        </body>
      </body>
    </body>
    </body>
  </worldbody>

   <actuator>
    <motor ctrllimited="true" ctrlrange="-1.0 1.0" joint="hip_1" gear="150"/>
    <motor ctrllimited="true" ctrlrange="-1.0 1.0" joint="ankle_1" gear="150"/>
    <motor ctrllimited="true" ctrlrange="-1.0 1.0" joint="hip_2" gear="150"/>
    <motor ctrllimited="true" ctrlrange="-1.0 1.0" joint="ankle_2" gear="150"/>
    <motor ctrllimited="true" ctrlrange="-1.0 1.0" joint="hip_3" gear="150"/>
    <motor ctrllimited="true" ctrlrange="-1.0 1.0" joint="ankle_3" gear="150"/>
    <motor ctrllimited="true" ctrlrange="-1.0 1.0" joint="hip_4" gear="150"/>
    <motor ctrllimited="true" ctrlrange="-1.0 1.0" joint="ankle_4" gear="150"/>
    <motor ctrllimited="true" ctrlrange="-1.0 1.0" joint="hip_5" gear="150"/>
    <motor ctrllimited="true" ctrlrange="-1.0 1.0" joint="ankle_5" gear="150"/>
    <motor ctrllimited="true" ctrlrange="-1.0 1.0" joint="hip_6" gear="150"/>
    <motor ctrllimited="true" ctrlrange="-1.0 1.0" joint="ankle_6" gear="150"/>
  </actuator>
  <!--
  <sensor>
    <velocimeter name='torso_velocimeter' site='sensorsurf'/>
    <gyro name='torso_gyro' site='sensorsurf'/>
  </sensor>
-->
</mujoco>
